<?xml version="1.0" ?>
<!-- =================================================================================== -->
<!-- |    This document was autogenerated by xacro from yumi.urdf.xacro                | -->
<!-- |    EDITING THIS FILE BY HAND IS NOT RECOMMENDED                                 | -->
<!-- =================================================================================== -->
<robot name="yumi">
  <material name="Black">
    <color rgba="0.0 0.0 0.0 1.0"/>
  </material>
  <material name="Blue">
    <color rgba="0.0 0.0 0.8 1.0"/>
  </material>
  <material name="Green">
    <color rgba="0.0 0.8 0.0 1.0"/>
  </material>
  <material name="Grey">
    <color rgba="0.5 0.5 0.5 1.0"/>
  </material>
  <material name="Light_Grey">
    <color rgba="0.8 0.8 0.8 1.0"/>
  </material>
  <material name="Ivory">
    <color rgba="1.0 1.0 0.94 1.0"/>
  </material>
  <material name="Orange">
    <color rgba="1.0 0.4235294117647059 0.0392156862745098 1.0"/>
  </material>
  <material name="Brown">
    <color rgba="0.8705882352941177 0.8117647058823529 0.7647058823529411 1.0"/>
  </material>
  <material name="Red">
    <color rgba="0.8 0.0 0.0 1.0"/>
  </material>
  <material name="White">
    <color rgba="1.0 1.0 1.0 1.0"/>
  </material>
  <gazebo>
    <plugin filename="libgazebo_ros_control.so" name="gazebo_ros_controller">
      <robotNamespace>/yumi</robotNamespace>
    </plugin>
  </gazebo>
  <link name="yumi_base_link"/>
  <joint name="yumi_base_link_to_body" type="fixed">
    <parent link="yumi_base_link"/>
    <child link="yumi_body"/>
    <origin rpy="0 0 0" xyz="0 0 0"/>
  </joint>
  <link name="yumi_body">
    <inertial>
      <origin rpy="0 0 0" xyz="0 0 0"/>
      <mass value="15"/>
      <inertia ixx="0.5" ixy="0" ixz="0" iyy="0.6" iyz="0" izz="0.3"/>
    </inertial>
    <visual>
      <origin rpy="0 0 0" xyz="0 0 0"/>
      <geometry>
        <mesh filename="package://yumi_description/meshes/body.stl"/>
      </geometry>
      <material name="Light_Grey"/>
    </visual>
    <collision>
      <origin rpy="0 0 0" xyz="0 0 0"/>
      <geometry>
        <mesh filename="package://yumi_description/meshes/coarse/body.stl"/>
      </geometry>
      <material name="Light_Grey"/>
    </collision>
  </link>
  <!--///////////////////////////////////// RIGHT ARM ////////////////////////////////  -->
  <!-- joint between body and link_1_r -->
  <joint name="yumi_joint_1_r" type="revolute">
    <parent link="yumi_body"/>
    <child link="yumi_link_1_r"/>
    <origin rpy="-0.9795   -0.5682   -2.3155" xyz="0.05355 -0.0725 0.41492"/>
    <axis xyz="0 0 1"/>
    <limit effort="300" lower="-2.940879789610445" upper="2.940879789610445" velocity="3.141592653589793"/>
    <dynamics damping="0.5"/>
  </joint>
  <link name="yumi_link_1_r">
    <inertial>
      <origin rpy="0 0 0" xyz="0 -0.03 0.12"/>
      <mass value="2"/>
      <inertia ixx="0.1" ixy="0" ixz="0" iyy="0.1" iyz="0" izz="0.1"/>
    </inertial>
    <visual>
      <origin rpy="0 0 0" xyz="0 0 0"/>
      <geometry>
        <mesh filename="package://yumi_description/meshes/link_1.stl"/>
      </geometry>
      <material name="Grey"/>
    </visual>
    <collision>
      <origin rpy="0 0 0" xyz="0 0 0"/>
      <geometry>
        <mesh filename="package://yumi_description/meshes/coarse/link_1.stl"/>
      </geometry>
      <material name="Grey"/>
    </collision>
  </link>
  <!-- joint between link_1_r and link_2_r -->
  <joint name="yumi_joint_2_r" type="revolute">
    <parent link="yumi_link_1_r"/>
    <child link="yumi_link_2_r"/>
    <origin rpy="1.5707963267948966 0.0 0.0" xyz="0.03 0.0 0.1"/>
    <axis xyz="0 0 1"/>
    <limit effort="300" lower="-2.504547476611863" upper="0.7592182246175333" velocity="3.141592653589793"/>
    <dynamics damping="0.5"/>
  </joint>
  <link name="yumi_link_2_r">
    <inertial>
      <origin rpy="0 0 0" xyz="0 0 0"/>
      <mass value="2"/>
      <inertia ixx="0.1" ixy="0" ixz="0" iyy="0.1" iyz="0" izz="0.1"/>
    </inertial>
    <visual>
      <origin rpy="0 0 0" xyz="0 0 0"/>
      <geometry>
        <mesh filename="package://yumi_description/meshes/link_2.stl"/>
      </geometry>
      <material name="Grey"/>
    </visual>
    <collision>
      <origin rpy="0 0 0" xyz="0 0 0"/>
      <geometry>
        <mesh filename="package://yumi_description/meshes/coarse/link_2.stl"/>
      </geometry>
      <material name="Grey"/>
    </collision>
  </link>
  <!-- joint between link_2_r and link_3_r -->
  <joint name="yumi_joint_7_r" type="revolute">
    <parent link="yumi_link_2_r"/>
    <child link="yumi_link_3_r"/>
    <origin rpy="-1.5707963267948966 0.0 0.0" xyz="-0.03 0.17283 0.0"/>
    <axis xyz="0 0 1"/>
    <limit effort="300" lower="-2.940879789610445" upper="2.940879789610445" velocity="3.141592653589793"/>
    <dynamics damping="0.5"/>
  </joint>
  <link name="yumi_link_3_r">
    <inertial>
      <origin rpy="0 0 0" xyz="0 0 0"/>
      <mass value="2"/>
      <inertia ixx="0.1" ixy="0" ixz="0" iyy="0.1" iyz="0" izz="0.1"/>
    </inertial>
    <visual>
      <origin rpy="0 0 0" xyz="0 0 0"/>
      <geometry>
        <mesh filename="package://yumi_description/meshes/link_3.stl"/>
      </geometry>
      <material name="Grey"/>
    </visual>
    <collision>
      <origin rpy="0 0 0" xyz="0 0 0"/>
      <geometry>
        <mesh filename="package://yumi_description/meshes/coarse/link_3.stl"/>
      </geometry>
      <material name="Grey"/>
    </collision>
  </link>
  <!-- joint between link_3_r and link_4_r -->
  <joint name="yumi_joint_3_r" type="revolute">
    <parent link="yumi_link_3_r"/>
    <child link="yumi_link_4_r"/>
    <origin rpy="1.5707963267948966 -1.5707963267948966 0.0" xyz="-0.04188 0.0 0.07873"/>
    <axis xyz="0 0 1"/>
    <limit effort="300" lower="-2.155481626212997" upper="1.3962634015954636" velocity="3.141592653589793"/>
    <dynamics damping="0.5"/>
  </joint>
  <link name="yumi_link_4_r">
    <inertial>
      <origin rpy="0 0 0" xyz="0 0 0"/>
      <mass value="2"/>
      <inertia ixx="0.1" ixy="0" ixz="0" iyy="0.1" iyz="0" izz="0.1"/>
    </inertial>
    <visual>
      <origin rpy="0 0 0" xyz="0 0 0"/>
      <geometry>
        <mesh filename="package://yumi_description/meshes/link_4.stl"/>
      </geometry>
      <material name="Grey"/>
    </visual>
    <collision>
      <origin rpy="0 0 0" xyz="0 0 0"/>
      <geometry>
        <mesh filename="package://yumi_description/meshes/coarse/link_4.stl"/>
      </geometry>
      <material name="Grey"/>
    </collision>
  </link>
  <!-- joint between link_4_r and link_5_r -->
  <joint name="yumi_joint_4_r" type="revolute">
    <parent link="yumi_link_4_r"/>
    <child link="yumi_link_5_r"/>
    <origin rpy="-1.5707963267948966 0.0 0.0" xyz="0.0405 0.16461 0.0"/>
    <axis xyz="0 0 1"/>
    <limit effort="300" lower="-5.061454830783555" upper="5.061454830783555" velocity="6.981317007977318"/>
    <dynamics damping="0.5"/>
  </joint>
  <link name="yumi_link_5_r">
    <inertial>
      <origin rpy="0 0 0" xyz="0 0 0"/>
      <mass value="2"/>
      <inertia ixx="0.1" ixy="0" ixz="0" iyy="0.1" iyz="0" izz="0.1"/>
    </inertial>
    <visual>
      <origin rpy="0 0 0" xyz="0 0 0"/>
      <geometry>
        <mesh filename="package://yumi_description/meshes/link_5.stl"/>
      </geometry>
      <material name="Grey"/>
    </visual>
    <collision>
      <origin rpy="0 0 0" xyz="0 0 0"/>
      <geometry>
        <mesh filename="package://yumi_description/meshes/coarse/link_5.stl"/>
      </geometry>
      <material name="Grey"/>
    </collision>
  </link>
  <!-- joint between link_5_r and link_6_r -->
  <joint name="yumi_joint_5_r" type="revolute">
    <parent link="yumi_link_5_r"/>
    <child link="yumi_link_6_r"/>
    <origin rpy="1.5707963267948966 0.0 0.0" xyz="-0.027 0 0.10039"/>
    <axis xyz="0 0 1"/>
    <limit effort="300" lower="-1.53588974175501" upper="2.4085543677521746" velocity="6.981317007977318"/>
    <dynamics damping="0.5"/>
  </joint>
  <link name="yumi_link_6_r">
    <inertial>
      <origin rpy="0 0 0" xyz="0 0 0"/>
      <mass value="2"/>
      <inertia ixx="0.1" ixy="0" ixz="0" iyy="0.1" iyz="0" izz="0.1"/>
    </inertial>
    <visual>
      <origin rpy="0 0 0" xyz="0 0 0"/>
      <geometry>
        <mesh filename="package://yumi_description/meshes/link_6.stl"/>
      </geometry>
      <material name="Grey"/>
    </visual>
    <collision>
      <origin rpy="0 0 0" xyz="0 0 0"/>
      <geometry>
        <mesh filename="package://yumi_description/meshes/coarse/link_6.stl"/>
      </geometry>
      <material name="Grey"/>
    </collision>
  </link>
  <!-- joint between link_6_r and link_7_r -->
  <joint name="yumi_joint_6_r" type="revolute">
    <parent link="yumi_link_6_r"/>
    <child link="yumi_link_7_r"/>
    <origin rpy="-1.5707963267948966 0.0 0.0" xyz="0.027 0.029 0.0"/>
    <axis xyz="0 0 1"/>
    <limit effort="300" lower="-3.9968039870670142" upper="3.9968039870670142" velocity="6.981317007977318"/>
    <dynamics damping="0.5"/>
  </joint>
  <link name="yumi_link_7_r">
    <inertial>
      <origin rpy="0 0 0" xyz="0 0 0"/>
      <mass value="2"/>
      <inertia ixx="0.1" ixy="0" ixz="0" iyy="0.1" iyz="0" izz="0.1"/>
    </inertial>
    <visual>
      <origin rpy="0 0 0" xyz="0 0 0"/>
      <geometry>
        <mesh filename="package://yumi_description/meshes/link_7.stl"/>
      </geometry>
      <material name="Grey"/>
    </visual>
    <collision>
      <origin rpy="0 0 0" xyz="0 0 0"/>
      <geometry>
        <mesh filename="package://yumi_description/meshes/coarse/link_7.stl"/>
      </geometry>
      <material name="Grey"/>
    </collision>
  </link>
  <!--///////////////////////////////////// LEFT ARM ////////////////////////////////  -->
  <!-- joint between body and link_1_l -->
  <joint name="yumi_joint_1_l" type="revolute">
    <parent link="yumi_body"/>
    <child link="yumi_link_1_l"/>
    <origin rpy="0.9781 -0.5716 2.3180" xyz="0.05355 0.07250 0.41492"/>
    <axis xyz="0 0 1"/>
    <limit effort="300" lower="-2.940879789610445" upper="2.940879789610445" velocity="3.141592653589793"/>
    <dynamics damping="0.5"/>
  </joint>
  <link name="yumi_link_1_l">
    <inertial>
      <origin rpy="0 0 0" xyz="0 -0.03 0.12"/>
      <mass value="2"/>
      <inertia ixx="0.1" ixy="0" ixz="0" iyy="0.1" iyz="0" izz="0.1"/>
    </inertial>
    <visual>
      <origin rpy="0 0 0" xyz="0 0 0"/>
      <geometry>
        <mesh filename="package://yumi_description/meshes/link_1.stl"/>
      </geometry>
      <material name="Grey"/>
    </visual>
    <collision>
      <origin rpy="0 0 0" xyz="0 0 0"/>
      <geometry>
        <mesh filename="package://yumi_description/meshes/coarse/link_1.stl"/>
      </geometry>
      <material name="Grey"/>
    </collision>
  </link>
  <!-- joint between link_1_l and link_2_l -->
  <joint name="yumi_joint_2_l" type="revolute">
    <parent link="yumi_link_1_l"/>
    <child link="yumi_link_2_l"/>
    <origin rpy="1.5707963267948966 0.0 0.0" xyz="0.03 0.0 0.1"/>
    <axis xyz="0 0 1"/>
    <limit effort="300" lower="-2.504547476611863" upper="0.7592182246175333" velocity="3.141592653589793"/>
    <dynamics damping="0.5"/>
  </joint>
  <link name="yumi_link_2_l">
    <inertial>
      <origin rpy="0 0 0" xyz="0 0 0"/>
      <mass value="2"/>
      <inertia ixx="0.1" ixy="0" ixz="0" iyy="0.1" iyz="0" izz="0.1"/>
    </inertial>
    <visual>
      <origin rpy="0 0 0" xyz="0 0 0"/>
      <geometry>
        <mesh filename="package://yumi_description/meshes/link_2.stl"/>
      </geometry>
      <material name="Grey"/>
    </visual>
    <collision>
      <origin rpy="0 0 0" xyz="0 0 0"/>
      <geometry>
        <mesh filename="package://yumi_description/meshes/coarse/link_2.stl"/>
      </geometry>
      <material name="Grey"/>
    </collision>
  </link>
  <!-- joint between link_2_l and link_3_l -->
  <joint name="yumi_joint_7_l" type="revolute">
    <parent link="yumi_link_2_l"/>
    <child link="yumi_link_3_l"/>
    <origin rpy="-1.5707963267948966 0.0 0.0" xyz="-0.03 0.17283 0.0"/>
    <axis xyz="0 0 1"/>
    <limit effort="300" lower="-2.940879789610445" upper="2.940879789610445" velocity="3.141592653589793"/>
    <dynamics damping="0.5"/>
  </joint>
  <link name="yumi_link_3_l">
    <inertial>
      <origin rpy="0 0 0" xyz="0 0 0"/>
      <mass value="2"/>
      <inertia ixx="0.1" ixy="0" ixz="0" iyy="0.1" iyz="0" izz="0.1"/>
    </inertial>
    <visual>
      <origin rpy="0 0 0" xyz="0 0 0"/>
      <geometry>
        <mesh filename="package://yumi_description/meshes/link_3.stl"/>
      </geometry>
      <material name="Grey"/>
    </visual>
    <collision>
      <origin rpy="0 0 0" xyz="0 0 0"/>
      <geometry>
        <mesh filename="package://yumi_description/meshes/coarse/link_3.stl"/>
      </geometry>
      <material name="Grey"/>
    </collision>
  </link>
  <!-- joint between link_3_l and link_4_l -->
  <joint name="yumi_joint_3_l" type="revolute">
    <parent link="yumi_link_3_l"/>
    <child link="yumi_link_4_l"/>
    <origin rpy="1.5707963267948966 -1.5707963267948966 0.0" xyz="-0.04188 0.0 0.07873"/>
    <axis xyz="0 0 1"/>
    <limit effort="300" lower="-2.155481626212997" upper="1.3962634015954636" velocity="3.141592653589793"/>
    <dynamics damping="0.5"/>
  </joint>
  <link name="yumi_link_4_l">
    <inertial>
      <origin rpy="0 0 0" xyz="0 0 0"/>
      <mass value="2"/>
      <inertia ixx="0.1" ixy="0" ixz="0" iyy="0.1" iyz="0" izz="0.1"/>
    </inertial>
    <visual>
      <origin rpy="0 0 0" xyz="0 0 0"/>
      <geometry>
        <mesh filename="package://yumi_description/meshes/link_4.stl"/>
      </geometry>
      <material name="Grey"/>
    </visual>
    <collision>
      <origin rpy="0 0 0" xyz="0 0 0"/>
      <geometry>
        <mesh filename="package://yumi_description/meshes/coarse/link_4.stl"/>
      </geometry>
      <material name="Grey"/>
    </collision>
  </link>
  <!-- joint between link_4_l and link_5_l -->
  <joint name="yumi_joint_4_l" type="revolute">
    <parent link="yumi_link_4_l"/>
    <child link="yumi_link_5_l"/>
    <origin rpy="-1.5707963267948966 0.0 0.0" xyz="0.0405 0.16461 0.0"/>
    <axis xyz="0 0 1"/>
    <limit effort="300" lower="-5.061454830783555" upper="5.061454830783555" velocity="6.981317007977318"/>
    <dynamics damping="0.5"/>
  </joint>
  <link name="yumi_link_5_l">
    <inertial>
      <origin rpy="0 0 0" xyz="0 0 0"/>
      <mass value="2"/>
      <inertia ixx="0.1" ixy="0" ixz="0" iyy="0.1" iyz="0" izz="0.1"/>
    </inertial>
    <visual>
      <origin rpy="0 0 0" xyz="0 0 0"/>
      <geometry>
        <mesh filename="package://yumi_description/meshes/link_5.stl"/>
      </geometry>
      <material name="Grey"/>
    </visual>
    <collision>
      <origin rpy="0 0 0" xyz="0 0 0"/>
      <geometry>
        <mesh filename="package://yumi_description/meshes/coarse/link_5.stl"/>
      </geometry>
      <material name="Grey"/>
    </collision>
  </link>
  <!-- joint between link_5_l and link_6_l -->
  <joint name="yumi_joint_5_l" type="revolute">
    <parent link="yumi_link_5_l"/>
    <child link="yumi_link_6_l"/>
    <origin rpy="1.5707963267948966 0.0 0.0" xyz="-0.027 0 0.10039"/>
    <axis xyz="0 0 1"/>
    <limit effort="300" lower="-1.53588974175501" upper="2.4085543677521746" velocity="6.981317007977318"/>
    <dynamics damping="0.5"/>
  </joint>
  <link name="yumi_link_6_l">
    <inertial>
      <origin rpy="0 0 0" xyz="0 0 0"/>
      <mass value="2"/>
      <inertia ixx="0.1" ixy="0" ixz="0" iyy="0.1" iyz="0" izz="0.1"/>
    </inertial>
    <visual>
      <origin rpy="0 0 0" xyz="0 0 0"/>
      <geometry>
        <mesh filename="package://yumi_description/meshes/link_6.stl"/>
      </geometry>
      <material name="Grey"/>
    </visual>
    <collision>
      <origin rpy="0 0 0" xyz="0 0 0"/>
      <geometry>
        <mesh filename="package://yumi_description/meshes/coarse/link_6.stl"/>
      </geometry>
      <material name="Grey"/>
    </collision>
  </link>
  <!-- joint between link_6_l and link_7_l -->
  <joint name="yumi_joint_6_l" type="revolute">
    <parent link="yumi_link_6_l"/>
    <child link="yumi_link_7_l"/>
    <origin rpy="-1.5707963267948966 0.0 0.0" xyz="0.027 0.029 0.0"/>
    <axis xyz="0 0 1"/>
    <limit effort="300" lower="-3.9968039870670142" upper="3.9968039870670142" velocity="6.981317007977318"/>
    <dynamics damping="0.5"/>
  </joint>
  <link name="yumi_link_7_l">
    <inertial>
      <origin rpy="0 0 0" xyz="0 0 0"/>
      <mass value="2"/>
      <inertia ixx="0.1" ixy="0" ixz="0" iyy="0.1" iyz="0" izz="0.1"/>
    </inertial>
    <visual>
      <origin rpy="0 0 0" xyz="0 0 0"/>
      <geometry>
        <mesh filename="package://yumi_description/meshes/link_7.stl"/>
      </geometry>
      <material name="Grey"/>
    </visual>
    <collision>
      <origin rpy="0 0 0" xyz="0 0 0"/>
      <geometry>
        <mesh filename="package://yumi_description/meshes/coarse/link_7.stl"/>
      </geometry>
      <material name="Grey"/>
    </collision>
  </link>
  <!-- Gazebo reference frame -->
  <gazebo reference="yumi_body">
    <material>Gazebo/Ivory</material>
    <mu1>0.2</mu1>
    <mu2>0.2</mu2>
  </gazebo>
  <transmission name="yumi_tran_1_r">
    <type>transmission_interface/SimpleTransmission</type>
    <joint name="yumi_joint_1_r">
      <hardwareInterface>hardware_interface/PositionJointInterface</hardwareInterface>
    </joint>
    <actuator name="yumi_motor_1_r">
      <hardwareInterface>hardware_interface/PositionJointInterface</hardwareInterface>
      <mechanicalReduction>1</mechanicalReduction>
    </actuator>
  </transmission>
  <transmission name="yumi_tran_2_r">
    <type>transmission_interface/SimpleTransmission</type>
    <joint name="yumi_joint_2_r">
      <hardwareInterface>hardware_interface/PositionJointInterface</hardwareInterface>
    </joint>
    <actuator name="yumi_motor_2_r">
      <hardwareInterface>hardware_interface/PositionJointInterface</hardwareInterface>
      <mechanicalReduction>1</mechanicalReduction>
    </actuator>
  </transmission>
  <transmission name="yumi_tran_3_r">
    <type>transmission_interface/SimpleTransmission</type>
    <joint name="yumi_joint_3_r">
      <hardwareInterface>hardware_interface/PositionJointInterface</hardwareInterface>
    </joint>
    <actuator name="yumi_motor_3_r">
      <hardwareInterface>hardware_interface/PositionJointInterface</hardwareInterface>
      <mechanicalReduction>1</mechanicalReduction>
    </actuator>
  </transmission>
  <transmission name="yumi_tran_4_r">
    <type>transmission_interface/SimpleTransmission</type>
    <joint name="yumi_joint_4_r">
      <hardwareInterface>hardware_interface/PositionJointInterface</hardwareInterface>
    </joint>
    <actuator name="yumi_motor_4_r">
      <hardwareInterface>hardware_interface/PositionJointInterface</hardwareInterface>
      <mechanicalReduction>1</mechanicalReduction>
    </actuator>
  </transmission>
  <transmission name="yumi_tran_5_r">
    <type>transmission_interface/SimpleTransmission</type>
    <joint name="yumi_joint_5_r">
      <hardwareInterface>hardware_interface/PositionJointInterface</hardwareInterface>
    </joint>
    <actuator name="yumi_motor_5_r">
      <hardwareInterface>hardware_interface/PositionJointInterface</hardwareInterface>
      <mechanicalReduction>1</mechanicalReduction>
    </actuator>
  </transmission>
  <transmission name="yumi_tran_6_r">
    <type>transmission_interface/SimpleTransmission</type>
    <joint name="yumi_joint_6_r">
      <hardwareInterface>hardware_interface/PositionJointInterface</hardwareInterface>
    </joint>
    <actuator name="yumi_motor_6_r">
      <hardwareInterface>hardware_interface/PositionJointInterface</hardwareInterface>
      <mechanicalReduction>1</mechanicalReduction>
    </actuator>
  </transmission>
  <transmission name="yumi_tran_7_r">
    <type>transmission_interface/SimpleTransmission</type>
    <joint name="yumi_joint_7_r">
      <hardwareInterface>hardware_interface/PositionJointInterface</hardwareInterface>
    </joint>
    <actuator name="yumi_motor_7_r">
      <hardwareInterface>hardware_interface/PositionJointInterface</hardwareInterface>
      <mechanicalReduction>1</mechanicalReduction>
    </actuator>
  </transmission>
  <transmission name="yumi_tran_1_l">
    <type>transmission_interface/SimpleTransmission</type>
    <joint name="yumi_joint_1_l">
      <hardwareInterface>hardware_interface/PositionJointInterface</hardwareInterface>
    </joint>
    <actuator name="yumi_motor_1_l">
      <hardwareInterface>hardware_interface/PositionJointInterface</hardwareInterface>
      <mechanicalReduction>1</mechanicalReduction>
    </actuator>
  </transmission>
  <transmission name="yumi_tran_2_l">
    <type>transmission_interface/SimpleTransmission</type>
    <joint name="yumi_joint_2_l">
      <hardwareInterface>hardware_interface/PositionJointInterface</hardwareInterface>
    </joint>
    <actuator name="yumi_motor_2_l">
      <hardwareInterface>hardware_interface/PositionJointInterface</hardwareInterface>
      <mechanicalReduction>1</mechanicalReduction>
    </actuator>
  </transmission>
  <transmission name="yumi_tran_3_l">
    <type>transmission_interface/SimpleTransmission</type>
    <joint name="yumi_joint_3_l">
      <hardwareInterface>hardware_interface/PositionJointInterface</hardwareInterface>
    </joint>
    <actuator name="yumi_motor_3_l">
      <hardwareInterface>hardware_interface/PositionJointInterface</hardwareInterface>
      <mechanicalReduction>1</mechanicalReduction>
    </actuator>
  </transmission>
  <transmission name="yumi_tran_4_l">
    <type>transmission_interface/SimpleTransmission</type>
    <joint name="yumi_joint_4_l">
      <hardwareInterface>hardware_interface/PositionJointInterface</hardwareInterface>
    </joint>
    <actuator name="yumi_motor_4_l">
      <hardwareInterface>hardware_interface/PositionJointInterface</hardwareInterface>
      <mechanicalReduction>1</mechanicalReduction>
    </actuator>
  </transmission>
  <transmission name="yumi_tran_5_l">
    <type>transmission_interface/SimpleTransmission</type>
    <joint name="yumi_joint_5_l">
      <hardwareInterface>hardware_interface/PositionJointInterface</hardwareInterface>
    </joint>
    <actuator name="yumi_motor_5_l">
      <hardwareInterface>hardware_interface/PositionJointInterface</hardwareInterface>
      <mechanicalReduction>1</mechanicalReduction>
    </actuator>
  </transmission>
  <transmission name="yumi_tran_6_l">
    <type>transmission_interface/SimpleTransmission</type>
    <joint name="yumi_joint_6_l">
      <hardwareInterface>hardware_interface/PositionJointInterface</hardwareInterface>
    </joint>
    <actuator name="yumi_motor_6_l">
      <hardwareInterface>hardware_interface/PositionJointInterface</hardwareInterface>
      <mechanicalReduction>1</mechanicalReduction>
    </actuator>
  </transmission>
  <transmission name="yumi_tran_7_l">
    <type>transmission_interface/SimpleTransmission</type>
    <joint name="yumi_joint_7_l">
      <hardwareInterface>hardware_interface/PositionJointInterface</hardwareInterface>
    </joint>
    <actuator name="yumi_motor_7_l">
      <hardwareInterface>hardware_interface/PositionJointInterface</hardwareInterface>
      <mechanicalReduction>1</mechanicalReduction>
    </actuator>
  </transmission>
  <!--joint between {parent} and base-->
  <joint name="yumi_link_7_r_joint" type="fixed">
    <origin rpy="0 0 3.141592653589793" xyz="0 0 0.007"/>
    <parent link="yumi_link_7_r"/>
    <child link="gripper_r_base"/>
  </joint>
  <link name="gripper_r_base">
    <inertial>
      <origin rpy="0 0 0" xyz="0 0 0"/>
      <mass value="0.2"/>
      <inertia ixx="0.0001" ixy="0" ixz="0" iyy="0.0001" iyz="0" izz="0.0001"/>
    </inertial>
    <visual>
      <origin rpy="0 0 0" xyz="0 0 0"/>
      <geometry>
        <mesh filename="package://yumi_description/meshes/gripper/base.stl"/>
      </geometry>
      <material name="Light_Grey"/>
    </visual>
    <collision>
      <origin rpy="0 0 0" xyz="0 0 0"/>
      <geometry>
        <mesh filename="package://yumi_description/meshes/gripper/coarse/base.stl"/>
      </geometry>
      <material name="Light_Grey"/>
    </collision>
  </link>
  <!-- joint between base and right finger -->
  <joint name="gripper_r_joint" type="prismatic">
    <parent link="gripper_r_base"/>
    <child link="gripper_r_finger_r"/>
    <origin rpy="0 0 0" xyz="0 -0.0065 0.0837"/>
    <axis xyz="-1 0 0"/>
    <limit effort="20" lower="0" upper="0.025" velocity="2"/>
    <dynamics damping="1.0"/>
  </joint>
  <link name="gripper_r_finger_r">
    <inertial>
      <mass value="0.04"/>
      <origin xyz="0 0 0"/>
      <inertia ixx="1.6666666666666667e-05" ixy="0.0" ixz="0.0" iyy="1.6666666666666667e-05" iyz="0.0" izz="1.6666666666666667e-05"/>
    </inertial>
    <visual>
      <origin rpy="0 0 0" xyz="0 0 0"/>
      <geometry>
        <mesh filename="package://yumi_description/meshes/gripper/finger.stl"/>
      </geometry>
      <material name="Blue"/>
    </visual>
    <collision>
      <origin rpy="0 0 0" xyz="0 0 0"/>
      <geometry>
        <mesh filename="package://yumi_description/meshes/gripper/coarse/finger.stl"/>
      </geometry>
      <material name="Blue"/>
    </collision>
  </link>
  <!-- joint between base and left finger -->
  <joint name="gripper_r_joint_m" type="prismatic">
    <parent link="gripper_r_base"/>
    <child link="gripper_r_finger_l"/>
    <origin rpy="0 0 3.141592653589793" xyz="0 0.0065 0.0837"/>
    <axis xyz="-1 0 0"/>
    <limit effort="20" lower="0" upper="0.025" velocity="2"/>
    <dynamics damping="1.0"/>
    <mimic joint="gripper_r_joint"/>
  </joint>
  <link name="gripper_r_finger_l">
    <inertial>
      <mass value="0.04"/>
      <origin xyz="0 0 0"/>
      <inertia ixx="1.6666666666666667e-05" ixy="0.0" ixz="0.0" iyy="1.6666666666666667e-05" iyz="0.0" izz="1.6666666666666667e-05"/>
    </inertial>
    <visual>
      <origin rpy="0 0 0" xyz="0 0 0"/>
      <geometry>
        <mesh filename="package://yumi_description/meshes/gripper/finger.stl"/>
      </geometry>
      <material name="Blue"/>
    </visual>
    <collision>
      <origin rpy="0 0 0" xyz="0 0 0"/>
      <geometry>
        <mesh filename="package://yumi_description/meshes/gripper/coarse/finger.stl"/>
      </geometry>
      <material name="Blue"/>
    </collision>
  </link>
  <!-- Plugin for the mimic o/c joint - AFAIK, that shouldn't be necessary any more starting with Gazebo 3.0 -->
  <gazebo>
    <plugin filename="libgazebo_mimic_plugin.so" name="mimic_plugin">
      <joint>gripper_r_joint</joint>
      <mimicJoint>gripper_r_joint_m</mimicJoint>
      <multiplier>1.0</multiplier>
    </plugin>
  </gazebo>
  <!-- body -->
  <gazebo reference="gripper_r_base">
    <material>Gazebo/Light_Grey</material>
    <mu1>0.2</mu1>
    <mu2>0.2</mu2>
  </gazebo>
  <transmission name="gripper_r_tran">
    <type>transmission_interface/SimpleTransmission</type>
    <joint name="gripper_r_joint">
      <hardwareInterface>hardware_interface/EffortJointInterface</hardwareInterface>
    </joint>
    <actuator name="gripper_r_motor">
      <hardwareInterface>hardware_interface/EffortJointInterface</hardwareInterface>
      <mechanicalReduction>1</mechanicalReduction>
    </actuator>
  </transmission>
  <!--joint between {parent} and base-->
  <joint name="yumi_link_7_l_joint" type="fixed">
    <origin rpy="0 0 3.141592653589793" xyz="0 0 0.007"/>
    <parent link="yumi_link_7_l"/>
    <child link="gripper_l_base"/>
  </joint>
  <link name="gripper_l_base">
    <inertial>
      <origin rpy="0 0 0" xyz="0 0 0"/>
      <mass value="0.2"/>
      <inertia ixx="0.0001" ixy="0" ixz="0" iyy="0.0001" iyz="0" izz="0.0001"/>
    </inertial>
    <visual>
      <origin rpy="0 0 0" xyz="0 0 0"/>
      <geometry>
        <mesh filename="package://yumi_description/meshes/gripper/base.stl"/>
      </geometry>
      <material name="Light_Grey"/>
    </visual>
    <collision>
      <origin rpy="0 0 0" xyz="0 0 0"/>
      <geometry>
        <mesh filename="package://yumi_description/meshes/gripper/coarse/base.stl"/>
      </geometry>
      <material name="Light_Grey"/>
    </collision>
  </link>
  <!-- joint between base and right finger -->
  <joint name="gripper_l_joint" type="prismatic">
    <parent link="gripper_l_base"/>
    <child link="gripper_l_finger_r"/>
    <origin rpy="0 0 0" xyz="0 -0.0065 0.0837"/>
    <axis xyz="-1 0 0"/>
    <limit effort="20" lower="0" upper="0.025" velocity="2"/>
    <dynamics damping="1.0"/>
  </joint>
  <link name="gripper_l_finger_r">
    <inertial>
      <mass value="0.04"/>
      <origin xyz="0 0 0"/>
      <inertia ixx="1.6666666666666667e-05" ixy="0.0" ixz="0.0" iyy="1.6666666666666667e-05" iyz="0.0" izz="1.6666666666666667e-05"/>
    </inertial>
    <visual>
      <origin rpy="0 0 0" xyz="0 0 0"/>
      <geometry>
        <mesh filename="package://yumi_description/meshes/gripper/finger.stl"/>
      </geometry>
      <material name="Blue"/>
    </visual>
    <collision>
      <origin rpy="0 0 0" xyz="0 0 0"/>
      <geometry>
        <mesh filename="package://yumi_description/meshes/gripper/coarse/finger.stl"/>
      </geometry>
      <material name="Blue"/>
    </collision>
  </link>
  <!-- joint between base and left finger -->
  <joint name="gripper_l_joint_m" type="prismatic">
    <parent link="gripper_l_base"/>
    <child link="gripper_l_finger_l"/>
    <origin rpy="0 0 3.141592653589793" xyz="0 0.0065 0.0837"/>
    <axis xyz="-1 0 0"/>
    <limit effort="20" lower="0" upper="0.025" velocity="2"/>
    <dynamics damping="1.0"/>
    <mimic joint="gripper_l_joint"/>
  </joint>
  <link name="gripper_l_finger_l">
    <inertial>
      <mass value="0.04"/>
      <origin xyz="0 0 0"/>
      <inertia ixx="1.6666666666666667e-05" ixy="0.0" ixz="0.0" iyy="1.6666666666666667e-05" iyz="0.0" izz="1.6666666666666667e-05"/>
    </inertial>
    <visual>
      <origin rpy="0 0 0" xyz="0 0 0"/>
      <geometry>
        <mesh filename="package://yumi_description/meshes/gripper/finger.stl"/>
      </geometry>
      <material name="Blue"/>
    </visual>
    <collision>
      <origin rpy="0 0 0" xyz="0 0 0"/>
      <geometry>
        <mesh filename="package://yumi_description/meshes/gripper/coarse/finger.stl"/>
      </geometry>
      <material name="Blue"/>
    </collision>
  </link>
  <!-- Plugin for the mimic o/c joint - AFAIK, that shouldn't be necessary any more starting with Gazebo 3.0 -->
  <gazebo>
    <plugin filename="libgazebo_mimic_plugin.so" name="mimic_plugin">
      <joint>gripper_l_joint</joint>
      <mimicJoint>gripper_l_joint_m</mimicJoint>
      <multiplier>1.0</multiplier>
    </plugin>
  </gazebo>
  <!-- body -->
  <gazebo reference="gripper_l_base">
    <material>Gazebo/Light_Grey</material>
    <mu1>0.2</mu1>
    <mu2>0.2</mu2>
  </gazebo>
  <transmission name="gripper_l_tran">
    <type>transmission_interface/SimpleTransmission</type>
    <joint name="gripper_l_joint">
      <hardwareInterface>hardware_interface/EffortJointInterface</hardwareInterface>
    </joint>
    <actuator name="gripper_l_motor">
      <hardwareInterface>hardware_interface/EffortJointInterface</hardwareInterface>
      <mechanicalReduction>1</mechanicalReduction>
    </actuator>
  </transmission>
  <material name="camera_aluminum">
    <color rgba="0.5 0.5 0.5 1"/>
  </material>
  <!-- camera body, with origin at bottom screw mount -->
  <joint name="camera_joint" type="fixed">
    <origin rpy="-1.5707963267948966 0 1.5707963267948966" xyz="0.01 0 0.16"/>
    <parent link="yumi_link_7_r"/>
    <child link="camera_bottom_screw_frame"/>
  </joint>
  <link name="camera_bottom_screw_frame"/>
  <joint name="camera_link_joint" type="fixed">
    <origin rpy="0 0 0" xyz="0 0.0175 0.0125"/>
    <parent link="camera_bottom_screw_frame"/>
    <child link="camera_link"/>
  </joint>
  <link name="camera_link">
    <visual>
      <origin rpy="1.5707963267948966 0 1.5707963267948966" xyz="0.0149 -0.0175 0"/>
      <geometry>
        <!-- <box size="${d435_cam_width} ${d435_cam_height} ${d435_cam_depth}"/> -->
        <mesh filename="package://realsense2_description/meshes/d435.dae"/>
        <!--<mesh filename="package://realsense2_description/meshes/d435/d435.dae" />-->
      </geometry>
      <material name="camera_aluminum"/>
    </visual>
    <collision>
      <origin rpy="0 0 0" xyz="0 -0.0175 0"/>
      <geometry>
        <box size="0.02505 0.09 0.025"/>
      </geometry>
    </collision>
    <inertial>
      <!-- The following are not reliable values, and should not be used for modeling -->
      <mass value="0.564"/>
      <origin xyz="0 0 0"/>
      <inertia ixx="0.003881243" ixy="0.0" ixz="0.0" iyy="0.000498940" iyz="0.0" izz="0.003879257"/>
    </inertial>
  </link>
  <!-- camera depth joints and links -->
  <joint name="camera_depth_joint" type="fixed">
    <origin rpy="0 0 0" xyz="0 0 0"/>
    <parent link="camera_link"/>
    <child link="camera_depth_frame"/>
  </joint>
  <link name="camera_depth_frame"/>
  <joint name="camera_depth_optical_joint" type="fixed">
    <origin rpy="-1.5707963267948966 0 -1.5707963267948966" xyz="0 0 0"/>
    <parent link="camera_depth_frame"/>
    <child link="camera_depth_optical_frame"/>
  </joint>
  <link name="camera_depth_optical_frame"/>
  <!-- camera left IR joints and links -->
  <joint name="camera_left_ir_joint" type="fixed">
    <origin rpy="0 0 0" xyz="0 0.0 0"/>
    <parent link="camera_depth_frame"/>
    <child link="camera_left_ir_frame"/>
  </joint>
  <link name="camera_left_ir_frame"/>
  <joint name="camera_left_ir_optical_joint" type="fixed">
    <origin rpy="-1.5707963267948966 0 -1.5707963267948966" xyz="0 0 0"/>
    <parent link="camera_left_ir_frame"/>
    <child link="camera_left_ir_optical_frame"/>
  </joint>
  <link name="camera_left_ir_optical_frame"/>
  <!-- camera right IR joints and links -->
  <joint name="camera_right_ir_joint" type="fixed">
    <origin rpy="0 0 0" xyz="0 -0.05 0"/>
    <parent link="camera_depth_frame"/>
    <child link="camera_right_ir_frame"/>
  </joint>
  <link name="camera_right_ir_frame"/>
  <joint name="camera_right_ir_optical_joint" type="fixed">
    <origin rpy="-1.5707963267948966 0 -1.5707963267948966" xyz="0 0 0"/>
    <parent link="camera_right_ir_frame"/>
    <child link="camera_right_ir_optical_frame"/>
  </joint>
  <link name="camera_right_ir_optical_frame"/>
  <!-- camera color joints and links -->
  <joint name="camera_color_joint" type="fixed">
    <origin rpy="0 0 0" xyz="0 0.015 0"/>
    <parent link="camera_depth_frame"/>
    <child link="camera_color_frame"/>
  </joint>
  <link name="camera_color_frame"/>
  <joint name="camera_color_optical_joint" type="fixed">
    <origin rpy="-1.5707963267948966 0 -1.5707963267948966" xyz="0 0 0"/>
    <parent link="camera_color_frame"/>
    <child link="camera_color_optical_frame"/>
  </joint>
  <link name="camera_color_optical_frame"/>
  <gazebo reference="camera_link">
    <self_collide>0</self_collide>
    <enable_wind>0</enable_wind>
    <kinematic>0</kinematic>
    <gravity>1</gravity>
    <!--<mu>1</mu>-->
    <mu2>1</mu2>
    <fdir1>0 0 0</fdir1>
    <!--<slip1>0</slip1>
      <slip2>0</slip2>-->
    <kp>1e+13</kp>
    <kd>1</kd>
    <!--<max_vel>0.01</max_vel>
      <min_depth>0</min_depth>-->
    <sensor name="cameracolor" type="camera">
      <camera name="camera">
        <horizontal_fov>1.2112585008840648</horizontal_fov>
        <image>
          <width>640</width>
          <height>480</height>
          <format>RGB_INT8</format>
        </image>
        <clip>
          <near>0.1</near>
          <far>100</far>
        </clip>
        <noise>
          <type>gaussian</type>
          <mean>0.0</mean>
          <stddev>0.007</stddev>
        </noise>
      </camera>
      <always_on>1</always_on>
      <update_rate>30</update_rate>
      <visualize>1</visualize>
    </sensor>
    <sensor name="cameraired1" type="camera">
      <camera name="camera">
        <horizontal_fov>1.4870205226991688</horizontal_fov>
        <image>
          <width>640</width>
          <height>480</height>
          <format>L_INT8</format>
        </image>
        <clip>
          <near>0.1</near>
          <far>100</far>
        </clip>
        <noise>
          <type>gaussian</type>
          <mean>0.0</mean>
          <stddev>0.05</stddev>
        </noise>
      </camera>
      <always_on>1</always_on>
      <update_rate>90</update_rate>
      <visualize>0</visualize>
    </sensor>
    <sensor name="cameraired2" type="camera">
      <camera name="camera">
        <horizontal_fov>1.4870205226991688</horizontal_fov>
        <image>
          <width>640</width>
          <height>480</height>
          <format>L_INT8</format>
        </image>
        <clip>
          <near>0.1</near>
          <far>100</far>
        </clip>
        <noise>
          <type>gaussian</type>
          <mean>0.0</mean>
          <stddev>0.05</stddev>
        </noise>
      </camera>
      <always_on>1</always_on>
      <update_rate>90</update_rate>
      <visualize>0</visualize>
    </sensor>
    <sensor name="cameradepth" type="depth">
      <camera name="camera">
        <horizontal_fov>1.4870205226991688</horizontal_fov>
        <image>
          <width>640</width>
          <height>480</height>
        </image>
        <clip>
          <near>0.1</near>
          <far>100</far>
        </clip>
        <noise>
          <type>gaussian</type>
          <mean>0.0</mean>
          <stddev>0.100</stddev>
        </noise>
      </camera>
      <always_on>1</always_on>
      <update_rate>90</update_rate>
      <visualize>0</visualize>
    </sensor>
  </gazebo>
  <gazebo>
    <plugin filename="librealsense_gazebo_plugin.so" name="camera">
      <prefix>camera</prefix>
      <depthUpdateRate>30.0</depthUpdateRate>
      <colorUpdateRate>30.0</colorUpdateRate>
      <infraredUpdateRate>30.0</infraredUpdateRate>
      <depthTopicName>depth/image_raw</depthTopicName>
      <depthCameraInfoTopicName>depth/camera_info</depthCameraInfoTopicName>
      <colorTopicName>color/image_raw</colorTopicName>
      <colorCameraInfoTopicName>color/camera_info</colorCameraInfoTopicName>
      <infrared1TopicName>infra1/image_raw</infrared1TopicName>
      <infrared1CameraInfoTopicName>infra1/camera_info</infrared1CameraInfoTopicName>
      <infrared2TopicName>infra2/image_raw</infrared2TopicName>
      <infrared2CameraInfoTopicName>infra2/camera_info</infrared2CameraInfoTopicName>
      <colorOpticalframeName>camera_color_optical_frame</colorOpticalframeName>
      <depthOpticalframeName>camera_depth_optical_frame</depthOpticalframeName>
      <infrared1OpticalframeName>camera_left_ir_optical_frame</infrared1OpticalframeName>
      <infrared2OpticalframeName>camera_right_ir_optical_frame</infrared2OpticalframeName>
      <rangeMinDepth>0.2</rangeMinDepth>
      <rangeMaxDepth>10.0</rangeMaxDepth>
      <pointCloud>True</pointCloud>
      <pointCloudTopicName>depth/color/points</pointCloudTopicName>
      <pointCloudCutoff>0.25</pointCloudCutoff>
      <pointCloudCutoffMax>9.0</pointCloudCutoffMax>
    </plugin>
  </gazebo>
  <link name="world"/>
  <joint name="world_joint" type="fixed">
    <parent link="world"/>
    <child link="yumi_base_link"/>
    <origin rpy="0 0 0" xyz="0 0 0.1"/>
  </joint>
</robot>
